Workbook

Sheet README
B1: Childcare Costing Model
B2: Uasin Gishu County markets — comparing four delivery models on cost, break-even and subsidy
B4: What this does
B5: It takes the cost figures collected on Section L of the questionnaire and works out, for each of the four delivery models, four things: what a child-day costs, how many children are needed to break even, how large a subsidy the County would have to carry, and what inclusion costs on its own.
B7: How to use it
B8: 1. Fill in the Assumptions sheet. Every blue cell is an input. Yellow cells are the ones that move the answer most — get those right first.
B10: 2. Fill in the Costs and Revenue sheets, one column per model. Blue cells only.
B12: 3. Read Comparison. Nothing there is typed; it is all calculated.
B14: 4. Read Sensitivity to see whether the ranking survives being wrong about the assumptions.
B16: Colour code
B17: Blue text = a number you type in. Black = calculated, do not overwrite. Green = pulled from another sheet. Yellow fill = an assumption worth arguing about.
B19: The figures currently in the workbook are placeholders
... B26: Break-even splits costs into fixed and variable. Staff are treated as fixed, but in reality they step up each time enrolment crosses the caregiver ratio, so the figure is an approximation that is most accurate near the enrolment you entered. Read it alongside the Sensitivity sheet rather than on its own.

Sheet Assumptions
A1: Assumptions
A2: Blue cells are inputs. Yellow marks the ones that move the answer most.
A4: Shared drivers
A5: Driver | B5: Value | G5: Where this comes from
A6: Days open per year | B6: 260 | G6: Trading days the centre operates. Section L6e.
A7: Children enrolled per day | B7: 40 | G7: Expected enrolment, not places. Section L6b.
A8: Attendance rate | B8: 0.8 | G8: Share of enrolled children present on a given day. L6c.
A9: Fee charged per child per day | B9: 60 | G9: The price being tested. Cross-check against G1/G2.
A10: Fee collection rate | B10: 0.85 | G10: Share of fees actually collected. G10 and G11.
A11: Caregiver to child ratio (1 to N) | B11: 10 | G11: Enforced minimum from the county interview, section 1.
A12: Food cost per child per day | B12: 35 | G12: Porridge and lunch. L5a.
A13: Consumables per child per day | B13: 8 | G13: Soap, cleaning, first aid. L5d and L5e.
A14: Statutory on-costs (NSSF, SHA, leave) | B14: 0.18 | G14: Applied to all salaries. Confirm current rates.
A15: Building works life (years) | B15: 15 | G15: For spreading one-off works. L2.
A16: Equipment and training life (years) | B16: 5 | G16: Furniture, play materials, initial training.
A17: Levy per trader per month | B17: 0 | G17: Only if a market-fee levy is used. G12a.
... A19: County subsidy per month | B19: 0 | G19: Any direct county contribution.
A21: Imputation switches — 1 = Yes, 0 = No
A22: Charge rent to the county model | B22: 1 | G22: Leave at 1. Setting 0 treats a county-owned building as free and rigs the comparison.
A23: Charge full cost for seconded staff | B23: 1 | G23: Leave at 1. Seconded ECDE staff are a real cost the County already carries.
A25: By model
A26: Driver | C26: County-run | D26: Private operator | E26: Partnership (PPP) | F26: Trader committee | G26: Where this comes from
A27: Rent applies (1 = yes, 0 = no) | C27: 1 | D27: 1 | E27: 1 | F27: 0 | G27: County pays imputed rent only if the switch above is on; the formula handles it.
A28: Rent per month (market rate) | C28: 25000 | D28: 25000 | E28: 25000 | F28: 0 | G28: What the space would let for. L5f.
A29: Caregiver pay, per month | C29: 22000 | D29: 18000 | E29: 20000 | F29: 14000 | G29: County on ECDE scale; private at market rate; committee typically lowest. L4a.
A30: Supervisor pay, per month | C30: 35000 | D30: 30000 | E30: 32000 | F30: 0 | G30: L4c.
A31: Cook pay, per month | C31: 14000 | D31: 13000 | E31: 13500 | F31: 12000 | G31: L4d.
A32: Cleaner pay, per month | C32: 12000 | D32: 11000 | E32: 11500 | F32: 10000 | G32: L4e.
A33: Security pay, per month | C33: 15000 | D33: 14000 | E33: 14500 | F33: 0 | G33: L4f.
A34: Admin overhead, % of staff cost | C34: 0.12 | D34: 0.1 | E34: 0.11 | F34: 0.04 | G34: County overhead is absorbed elsewhere — impute it, do not zero it. L5j.
A35: Operator margin, % of total cost | C35: 0 | D35: 0.12 | E35: 0.06 | F35: 0 | G35: A private operator will not run at cost. L8d.
A36: Cost of collecting fees, % of fees | C36: 0.02 | D36: 0.02 | E36: 0.02 | F36: 0.06 | G36: Highest where traders collect from each other. L5k.
A37: Utilities per month | C37: 6000 | D37: 6000 | E37: 6000 | F37: 6000 | G37: L5b and L5c.
A38: Maintenance per year | C38: 40000 | D38: 40000 | E38: 40000 | F38: 25000 | G38: L5g.
... A40: Licence renewal per year | C40: 8000 | D40: 8000 | E40: 8000 | F40: 8000 | G40: L5i.
A42: Every figure above is a placeholder. Replace each one before quoting any result.

Sheet Costs
A1: Costs
A2: One column per model. Blue cells are inputs; black cells calculate.
A5: Cost line | C5: County-run | D5: Private operator | E5: Partnership (PPP) | F5: Trader committee | G5: Note
A6: One-off capital costs — works (L2)
A7: Building repair or conversion | C7: 450000 | D7: 450000 | E7: 450000 | F7: 450000 | G7: L2a. From the facility assessment.
A8: Water connection or tank | C8: 80000 | D8: 80000 | E8: 80000 | F8: 80000 | G8: L2b.
A9: Toilets and handwashing | C9: 180000 | D9: 180000 | E9: 180000 | F9: 180000 | G9: L2c.
A10: Kitchen / food preparation | C10: 120000 | D10: 120000 | E10: 120000 | F10: 90000 | G10: L2d.
A11: Safety works | C11: 90000 | D11: 90000 | E11: 90000 | F11: 70000 | G11: L2e.
A12: Electrical works and lighting | C12: 70000 | D12: 70000 | E12: 70000 | F12: 70000 | G12: L2f.
A13: Subtotal — works | C13: =SUM(C7:C12) | D13: =SUM(D7:D12) | E13: =SUM(E7:E12) | F13: =SUM(F7:F12)
A14: One-off capital costs — equipment and setup (L2)
A15: Furniture, mats, cots, play materials | C15: 150000 | D15: 150000 | E15: 150000 | F15: 110000 | G15: L2g.
A16: Initial caregiver training | C16: 120000 | D16: 120000 | E16: 120000 | F16: 60000 | G16: L2h.
A17: Registration and licensing fees | C17: 25000 | D17: 25000 | E17: 25000 | F17: 25000 | G17: L2i.
A18: Subtotal — equipment and setup | C18: =SUM(C15:C17) | D18: =SUM(D15:D17) | E18: =SUM(E15:E17) | F18: =SUM(F15:F17)
A19: Making the space accessible (L3) — kept separate on purpose
A20: Ramp | C20: 60000 | D20: 60000 | E20: 60000 | F20: 60000 | G20: L3a.
A21: Widening doors to 800mm | C21: 35000 | D21: 35000 | E21: 35000 | F21: 35000 | G21: L3b.
A22: Accessible toilet | C22: 95000 | D22: 95000 | E22: 95000 | F22: 95000 | G22: L3c.
A23: Levelling the route from stalls | C23: 55000 | D23: 55000 | E23: 55000 | F23: 55000 | G23: L3d.
A24: Subtotal — inclusion, one-off | C24: =SUM(C20:C23) | D24: =SUM(D20:D23) | E24: =SUM(E20:E23) | F24: =SUM(F20:F23) | G24: Feeds L3h and the Comparison sheet.
A25: Annualised capital cost | C25: =(C13+C24)/Assumptions!$B$15+C18/Assumptions!$B$16 | D25: =(D13+D24)/Assumptions!$B$15+D18/Assumptions!$B$16 | E25: =(E13+E24)/Assumptions!$B$15+E18/Assumptions!$B$16 | F25: =(F13+F24)/Assumptions!$B$15+F18/Assumptions!$B$16 | G25: Works and accessibility spread over the building life; equipment and training over the shorter life.
A27: Annual staff cost (L4)
A28: Caregivers needed (children ÷ ratio, rounded up) | C28: =ROUNDUP(Assumptions!$B$7/Assumptions!$B$11,0) | D28: =ROUNDUP(Assumptions!$B$7/Assumptions!$B$11,0) | E28: =ROUNDUP(Assumptions!$B$7/Assumptions!$B$11,0) | F28: =ROUNDUP(Assumptions!$B$7/Assumptions!$B$11,0) | G28: Steps up each time enrolment crosses the ratio.
A29: Extra caregiver time for inclusion (full-time equivalents) | C29: 0.5 | D29: 0.5 | E29: 0.5 | F29: 0.5 | G29: L3f. A lower ratio for children who need more support.
A30: Caregivers | C30: =C28*Assumptions!$C$29*12*(1+Assumptions!$B$14) | D30: =D28*Assumptions!$D$29*12*(1+Assumptions!$B$14) | E30: =E28*Assumptions!$E$29*12*(1+Assumptions!$B$14) | F30: =F28*Assumptions!$F$29*12*(1+Assumptions!$B$14) | G30: L4a.
A31: Supervisor | C31: =Assumptions!$C$30*12*(1+Assumptions!$B$14) | D31: =Assumptions!$D$30*12*(1+Assumptions!$B$14) | E31: =Assumptions!$E$30*12*(1+Assumptions!$B$14) | F31: =Assumptions!$F$30*12*(1+Assumptions!$B$14)
A32: Cook | C32: =Assumptions!$C$31*12*(1+Assumptions!$B$14) | D32: =Assumptions!$D$31*12*(1+Assumptions!$B$14) | E32: =Assumptions!$E$31*12*(1+Assumptions!$B$14) | F32: =Assumptions!$F$31*12*(1+Assumptions!$B$14)
A33: Cleaner | C33: =Assumptions!$C$32*12*(1+Assumptions!$B$14) | D33: =Assumptions!$D$32*12*(1+Assumptions!$B$14) | E33: =Assumptions!$E$32*12*(1+Assumptions!$B$14) | F33: =Assumptions!$F$32*12*(1+Assumptions!$B$14)
A34: Security | C34: =Assumptions!$C$33*12*(1+Assumptions!$B$14) | D34: =Assumptions!$D$33*12*(1+Assumptions!$B$14) | E34: =Assumptions!$E$33*12*(1+Assumptions!$B$14) | F34: =Assumptions!$F$33*12*(1+Assumptions!$B$14)
A35: Inclusion — extra caregiver time | C35: =C29*Assumptions!$C$29*12*(1+Assumptions!$B$14) | D35: =D29*Assumptions!$D$29*12*(1+Assumptions!$B$14) | E35: =E29*Assumptions!$E$29*12*(1+Assumptions!$B$14) | F35: =F29*Assumptions!$F$29*12*(1+Assumptions!$B$14) | G35: Part of the inclusion cost; also counted in the inclusion line below.
A36: Subtotal — staff | C36: =SUM(C30:C35) | D36: =SUM(D30:D35) | E36: =SUM(E30:E35) | F36: =SUM(F30:F35)
A37: Seconded-staff adjustment | C37: =IF(Assumptions!$B$23=1,0,-C36) | D37: =0 | E37: =0 | F37: =0 | G37: Zero while the switch is on, which is how it should stay. If the switch is turned off, county staff cost drops out entirely — that is what makes the comparison unfair.
A39: Other annual running costs (L5)
A40: Food | C40: =Assumptions!$B$7*Assumptions!$B$8*Assumptions!$B$6*Assumptions!$B$12 | D40: =Assumptions!$B$7*Assumptions!$B$8*Assumptions!$B$6*Assumptions!$B$12 | E40: =Assumptions!$B$7*Assumptions!$B$8*Assumptions!$B$6*Assumptions!$B$12 | F40: =Assumptions!$B$7*Assumptions!$B$8*Assumptions!$B$6*Assumptions!$B$12 | G40: L5a. Varies with the number of children.
A41: Consumables, cleaning and first aid | C41: =Assumptions!$B$7*Assumptions!$B$8*Assumptions!$B$6*Assumptions!$B$13 | D41: =Assumptions!$B$7*Assumptions!$B$8*Assumptions!$B$6*Assumptions!$B$13 | E41: =Assumptions!$B$7*Assumptions!$B$8*Assumptions!$B$6*Assumptions!$B$13 | F41: =Assumptions!$B$7*Assumptions!$B$8*Assumptions!$B$6*Assumptions!$B$13
A42: Utilities | C42: =Assumptions!$C$37*12 | D42: =Assumptions!$D$37*12 | E42: =Assumptions!$E$37*12 | F42: =Assumptions!$F$37*12
A43: Rent or space charge | C43: =IF(Assumptions!$B$22=1,Assumptions!$C$28*12*Assumptions!$C$27,0) | D43: =Assumptions!$D$28*12*Assumptions!$D$27 | E43: =Assumptions!$E$28*12*Assumptions!$E$27 | F43: =Assumptions!$F$28*12*Assumptions!$F$27 | G43: L5f. The county model pays imputed rent while the switch is on.
A44: Maintenance and repairs | C44: =Assumptions!$C$38 | D44: =Assumptions!$D$38 | E44: =Assumptions!$E$38 | F44: =Assumptions!$F$38
...

Sheet Revenue
A1: Revenue
A2: Money coming in each year, per model (Section L7).
A5: Source | C5: County-run | D5: Private operator | E5: Partnership (PPP) | F5: Trader committee | G5: Note
A6: Child-days per year | C6: =Assumptions!$B$7*Assumptions!$B$8*Assumptions!$B$6 | D6: =Assumptions!$B$7*Assumptions!$B$8*Assumptions!$B$6 | E6: =Assumptions!$B$7*Assumptions!$B$8*Assumptions!$B$6 | F6: =Assumptions!$B$7*Assumptions!$B$8*Assumptions!$B$6 | G6: Children enrolled × attendance × days open. The denominator for cost per child-day.
A8: Fees from parents | C8: =C6*Assumptions!$B$9*Assumptions!$B$10 | D8: =D6*Assumptions!$B$9*Assumptions!$B$10 | E8: =E6*Assumptions!$B$9*Assumptions!$B$10 | F8: =F6*Assumptions!$B$9*Assumptions!$B$10 | G8: L7a. Net of what is not collected — see the collection rate on Assumptions.
A9: Market levy | C9: =Assumptions!$B$17*Assumptions!$B$18*12 | D9: =Assumptions!$B$17*Assumptions!$B$18*12 | E9: =Assumptions!$B$17*Assumptions!$B$18*12 | F9: =Assumptions!$B$17*Assumptions!$B$18*12 | G9: L7c. Zero unless a levy is used. G12a gives what traders would accept.
A10: County subsidy | C10: =Assumptions!$B$19*12 | D10: =Assumptions!$B$19*12 | E10: =Assumptions!$B$19*12 | F10: =Assumptions!$B$19*12 | G10: L7d.
A11: Donor or NGO support | C11: 0 | D11: 0 | E11: 0 | F11: 0 | G11: L7e.
A12: TOTAL ANNUAL REVENUE | C12: =SUM(C8:C11) | D12: =SUM(D8:D11) | E12: =SUM(E8:E11) | F12: =SUM(F8:F11)

Sheet Comparison
A1: Comparison
A2: Nothing on this sheet is typed. Change the inputs, not these cells.
A5: Result | C5: County-run | D5: Private operator | E5: Partnership (PPP) | F5: Trader committee | G5: How it is worked out
A6: Total annual cost | C6: =Costs!C51 | D6: =Costs!D51 | E6: =Costs!E51 | F6: =Costs!F51 | G6: From the Costs sheet.
A7: Total annual revenue | C7: =Revenue!C12 | D7: =Revenue!D12 | E7: =Revenue!E12 | F7: =Revenue!F12 | G7: From the Revenue sheet.
A9: Cost per child-day | C9: =IFERROR(Costs!C51/Revenue!C6,0) | D9: =IFERROR(Costs!D51/Revenue!D6,0) | E9: =IFERROR(Costs!E51/Revenue!E6,0) | F9: =IFERROR(Costs!F51/Revenue!F6,0) | G9: L9a. Total annual cost ÷ child-days. The number to compare models on.
A10: Annual shortfall the County must cover | C10: =Costs!C51-Revenue!C12 | D10: =Costs!D51-Revenue!D12 | E10: =Costs!E51-Revenue!E12 | F10: =Costs!F51-Revenue!F12 | G10: L9c. Cost minus revenue. This is the budget line.
A11: Shortfall per child-day | C11: =IFERROR((Costs!C51-Revenue!C12)/Revenue!C6,0) | D11: =IFERROR((Costs!D51-Revenue!D12)/Revenue!D6,0) | E11: =IFERROR((Costs!E51-Revenue!E12)/Revenue!E6,0) | F11: =IFERROR((Costs!F51-Revenue!F12)/Revenue!F6,0) | G11: The same gap, per child served per day.
A13: Variable cost per child-day | C13: =Assumptions!$B$12+Assumptions!$B$13 | D13: =Assumptions!$B$12+Assumptions!$B$13 | E13: =Assumptions!$B$12+Assumptions!$B$13 | F13: =Assumptions!$B$12+Assumptions!$B$13 | G13: Food and consumables — the costs that rise with each extra child.
A14: Fixed cost per year | C14: =Costs!C51-(Costs!C40+Costs!C41) | D14: =Costs!D51-(Costs!D40+Costs!D41) | E14: =Costs!E51-(Costs!E40+Costs!E41) | F14: =Costs!F51-(Costs!F40+Costs!F41) | G14: Everything else: staff, rent, utilities, insurance, overhead, annualised capital.
A15: Net fee received per child-day | C15: =Assumptions!$B$9*Assumptions!$B$10-C13 | D15: =Assumptions!$B$9*Assumptions!$B$10-D13 | E15: =Assumptions!$B$9*Assumptions!$B$10-E13 | F15: =Assumptions!$B$9*Assumptions!$B$10-F13 | G15: What one extra child-day contributes towards fixed costs.
A16: Children per day needed to break even | C16: =IF(C15<=0,"never at this fee",ROUNDUP(C14/(C15*Assumptions!$B$6*Assumptions!$B$8),0)) | D16: =IF(D15<=0,"never at this fee",ROUNDUP(D14/(D15*Assumptions!$B$6*Assumptions!$B$8),0)) | E16: =IF(E15<=0,"never at this fee",ROUNDUP(E14/(E15*Assumptions!$B$6*Assumptions!$B$8),0)) | F16: =IF(F15<=0,"never at this fee",ROUNDUP(F14/(F15*Assumptions!$B$6*Assumptions!$B$8),0)) | G16: L9b. If the fee does not cover food and consumables, no enrolment breaks even — the cell says so.
A17: Break-even fee per child-day at the enrolment entered | C17: =IFERROR(Costs!C51/(Revenue!C6*Assumptions!$B$10),0) | D17: =IFERROR(Costs!D51/(Revenue!D6*Assumptions!$B$10),0) | E17: =IFERROR(Costs!E51/(Revenue!E6*Assumptions!$B$10),0) | F17: =IFERROR(Costs!F51/(Revenue!F6*Assumptions!$B$10),0) | G17: What you would have to charge to cover costs at the enrolment on the Assumptions sheet. Compare against G1 and G2.
A19: Cost of inclusion, per year | C19: =Costs!C53 | D19: =Costs!D53 | E19: =Costs!E53 | F19: =Costs!F53 | G19: L9d. Accessibility works spread over the building life, plus the extra caregiver time.
A20: Cost of inclusion, per child-day | C20: =IFERROR(Costs!C53/Revenue!C6,0) | D20: =IFERROR(Costs!D53/Revenue!D6,0) | E20: =IFERROR(Costs!E53/Revenue!E6,0) | F20: =IFERROR(Costs!F53/Revenue!F6,0) | G20: What it would add to the fee if inclusion were funded by all parents rather than the County. Compare against H16a.
A23: Read the break-even figure alongside the Sensitivity sheet. Staff costs step up when enrolment crosses the caregiver ratio, so a break-even far from the enrolment you entered is only approximate.

Sheet Sensitivity
A1: Sensitivity
A2: Does the cheapest model stay the cheapest when the assumptions are wrong?
A4: Each row changes one thing and recomputes cost per child-day. Multipliers are inputs — change them to test your own scenarios.
A6: Scenario | B6: Enrolment × | C6: Fixed cost × | D6: County-run | E6: Private operator | F6: Partnership (PPP) | G6: Trader committee | I6: What it tests
A7: As entered (base case) | B7: 1 | C7: 1 | D7: =IFERROR((Comparison!$C$14*$C7)/(Assumptions!$B$7*$B7*Assumptions!$B$8*Assumptions!$B$6)+Comparison!$C$13,0) | E7: =IFERROR((Comparison!$D$14*$C7)/(Assumptions!$B$7*$B7*Assumptions!$B$8*Assumptions!$B$6)+Comparison!$D$13,0) | F7: =IFERROR((Comparison!$E$14*$C7)/(Assumptions!$B$7*$B7*Assumptions!$B$8*Assumptions!$B$6)+Comparison!$E$13,0) | G7: =IFERROR((Comparison!$F$14*$C7)/(Assumptions!$B$7*$B7*Assumptions!$B$8*Assumptions!$B$6)+Comparison!$F$13,0) | I7: The Assumptions sheet as it stands.
A8: Enrolment 30% lower | B8: 0.7 | C8: 1 | D8: =IFERROR((Comparison!$C$14*$C8)/(Assumptions!$B$7*$B8*Assumptions!$B$8*Assumptions!$B$6)+Comparison!$C$13,0) | E8: =IFERROR((Comparison!$D$14*$C8)/(Assumptions!$B$7*$B8*Assumptions!$B$8*Assumptions!$B$6)+Comparison!$D$13,0) | F8: =IFERROR((Comparison!$E$14*$C8)/(Assumptions!$B$7*$B8*Assumptions!$B$8*Assumptions!$B$6)+Comparison!$E$13,0) | G8: =IFERROR((Comparison!$F$14*$C8)/(Assumptions!$B$7*$B8*Assumptions!$B$8*Assumptions!$B$6)+Comparison!$F$13,0) | I8: Fewer children than hoped — the most common way these fail.
A9: Enrolment 30% higher | B9: 1.3 | C9: 1 | D9: =IFERROR((Comparison!$C$14*$C9)/(Assumptions!$B$7*$B9*Assumptions!$B$8*Assumptions!$B$6)+Comparison!$C$13,0) | E9: =IFERROR((Comparison!$D$14*$C9)/(Assumptions!$B$7*$B9*Assumptions!$B$8*Assumptions!$B$6)+Comparison!$D$13,0) | F9: =IFERROR((Comparison!$E$14*$C9)/(Assumptions!$B$7*$B9*Assumptions!$B$8*Assumptions!$B$6)+Comparison!$E$13,0) | G9: =IFERROR((Comparison!$F$14*$C9)/(Assumptions!$B$7*$B9*Assumptions!$B$8*Assumptions!$B$6)+Comparison!$F$13,0) | I9: Demand exceeds the plan.
A10: Salaries and overheads 20% higher | B10: 1 | C10: 1.2 | D10: =IFERROR((Comparison!$C$14*$C10)/(Assumptions!$B$7*$B10*Assumptions!$B$8*Assumptions!$B$6)+Comparison!$C$13,0) | E10: =IFERROR((Comparison!$D$14*$C10)/(Assumptions!$B$7*$B10*Assumptions!$B$8*Assumptions!$B$6)+Comparison!$D$13,0) | F10: =IFERROR((Comparison!$E$14*$C10)/(Assumptions!$B$7*$B10*Assumptions!$B$8*Assumptions!$B$6)+Comparison!$E$13,0) | G10: =IFERROR((Comparison!$F$14*$C10)/(Assumptions!$B$7*$B10*Assumptions!$B$8*Assumptions!$B$6)+Comparison!$F$13,0) | I10: Pay pressure, or an underestimated staffing need.
A11: Low season | B11: 0.6 | C11: 1 | D11: =IFERROR((Comparison!$C$14*$C11)/(Assumptions!$B$7*$B11*Assumptions!$B$8*Assumptions!$B$6)+Comparison!$C$13,0) | E11: =IFERROR((Comparison!$D$14*$C11)/(Assumptions!$B$7*$B11*Assumptions!$B$8*Assumptions!$B$6)+Comparison!$D$13,0) | F11: =IFERROR((Comparison!$E$14*$C11)/(Assumptions!$B$7*$B11*Assumptions!$B$8*Assumptions!$B$6)+Comparison!$E$13,0) | G11: =IFERROR((Comparison!$F$14*$C11)/(Assumptions!$B$7*$B11*Assumptions!$B$8*Assumptions!$B$6)+Comparison!$F$13,0) | I11: Traders trade fewer days in some months (B21); fixed costs do not fall.
A12: Both: low enrolment and higher costs | B12: 0.7 | C12: 1.2 | D12: =IFERROR((Comparison!$C$14*$C12)/(Assumptions!$B$7*$B12*Assumptions!$B$8*Assumptions!$B$6)+Comparison!$C$13,0) | E12: =IFERROR((Comparison!$D$14*$C12)/(Assumptions!$B$7*$B12*Assumptions!$B$8*Assumptions!$B$6)+Comparison!$D$13,0) | F12: =IFERROR((Comparison!$E$14*$C12)/(Assumptions!$B$7*$B12*Assumptions!$B$8*Assumptions!$B$6)+Comparison!$E$13,0) | G12: =IFERROR((Comparison!$F$14*$C12)/(Assumptions!$B$7*$B12*Assumptions!$B$8*Assumptions!$B$6)+Comparison!$F$13,0) | I12: The pessimistic case. If the ranking holds here, it holds.
A14: Cheapest model in each scenario
A15: As entered (base case) | B15: =INDEX({"County-run","Private operator","Partnership (PPP)","Trader committee"},MATCH(MIN(D7:G7),D7:G7,0))
A16: Enrolment 30% lower | B16: =INDEX({"County-run","Private operator","Partnership (PPP)","Trader committee"},MATCH(MIN(D8:G8),D8:G8,0))
A17: Enrolment 30% higher | B17: =INDEX({"County-run","Private operator","Partnership (PPP)","Trader committee"},MATCH(MIN(D9:G9),D9:G9,0))
A18: Salaries and overheads 20% higher | B18: =INDEX({"County-run","Private operator","Partnership (PPP)","Trader committee"},MATCH(MIN(D10:G10),D10:G10,0))
A19: Low season | B19: =INDEX({"County-run","Private operator","Partnership (PPP)","Trader committee"},MATCH(MIN(D11:G11),D11:G11,0))
A20: Both: low enrolment and higher costs | B20: =INDEX({"County-run","Private operator","Partnership (PPP)","Trader committee"},MATCH(MIN(D12:G12),D12:G12,0))
A22: If the same name appears on every row, the recommendation is robust. If it changes, say so plainly and tell the County which figure decides it.
A23: Simplification: this sheet scales fixed costs by a single multiplier rather than rebuilding the staffing roster. It is a test of robustness, not a second model — for a specific scenario, change the Assumptions sheet itself and read Comparison.
